Про связь пространства имён и static

```cpp
#include <iostream>

static int foo() { return 1; }; // static определение ф-ции

class MyClass // static определение класса надопустимо
{
private:
public:
    int m;
    MyClass() : m(9) {}
    ~MyClass() {}
};

namespace
{
    class MyClass2
    {
    private:
    public:
        int m;
        MyClass2() : m(13) {}
        ~MyClass2() {}
    };
    int k = 7;
} // anonymous namespace

int k = 3;

int main()
{
    class std
    {
    private:
        int i;

    public:
        std() {}
        ~std() {}
    };

    MyClass a;
    ::std::cout << a.m;
}
```

```cpp
class A
{
    static int n;
    A(){};
    ~A(){};
};
 
int main()
{
    int A;
    A::n = 42; // OK
    A b;       // Ошибка
}
```

Подробнее об исключениях:

Был [пример](https://academy.yandex.ru/handbook/cpp/article/exceptions):
```cpp
#include <iostream>
 
struct WrongAgeException {
    int age;
};

int ReadAge() {
    std::cin.exceptions(std::istream::failbit);
    int age;
    std::cin >> age;
    if (age < 0 || age >= 128) {
        throw WrongAgeException(age);
    }
    return age;
}

int main() {
    try {
        age = ReadAge();  // может сгенерировать исключения разных типов
        // Работаем с возрастом age
    } catch (const WrongAgeException& ex) {
        std::cerr << "Age is not correct: " << ex.age << "\n";
        return 1;
    } catch (const std::istream::failure& ex) {
        std::cerr << "Failed to read age: " << ex.what() << "\n";
        return 1;
    } catch (...) {
        std::cerr << "Some other exception\n";
        return 1;
    }
}
```

```cpp
#include <exception>
#include <iostream>

class Logger
{
private:
    inline static int counter = 0;

    const int id; // константа должна быть проинициализирована в конструкторе

public:
    Logger() : id(++counter)
    { // инициализируем id текущего объекта
        std::cout << "Logger(): " << id << "\n";
    }

    Logger(const Logger &other) : id(++counter)
    {
        std::cout << "Logger(const Logger&): " << id << " " << other.id << "\n";
    }

    Logger &operator=(const Logger &other)
    {
        // Тут никакие счётчики не меняются, ведь объект уже создан
        std::cout << "Logger& operator = (const Logger&) " << id << " " << other.id << "\n";
        return *this;
    }

    ~Logger()
    {
        std::cout << "~Logger() " << id << "\n";
    }
};

void f()
{
    std::cout << "Welcome to f()!\n";
    Logger x;
    // ...
    throw std::exception(); // в какой-то момент происходит исключение
}

int main()
{
    try
    {
        Logger y;
        f();
    }
    catch (const std::exception &)
    {
        std::cout << "Something happened...\n";
        return 1;
    }
}
```

Стандартный класс [исключения](https://en.cppreference.com/w/cpp/error/exception) :
```cpp
class exception
{
public:
    exception() _GLIBCXX_NOTHROW {}
    virtual ~~exception() _GLIBCXX_TXN_SAFE_DYN _GLIBCXX_NOTHROW;
#if __cplusplus >= 201103L exception(const exception &) = default;
    exception &operator=(const exception &) = default;
    exception(exception &&) = default;
    exception &operator=(exception &&) = default;
#endif 
/** Returns a C-style character string describing the general cause * of the current error. */ 
virtual const char *
what() const _GLIBCXX_TXN_SAFE_DYN _GLIBCXX_NOTHROW;
};
```



```cpp
#include <iostream>
class person_error : public std::exception
{
public:
    person_error(const std::string &message) : message{message}
    {
    }
    const char *what() const noexcept override
    {
        return message.c_str(); // получаем из std::string строку const char*
    }

private:
    std::string message; // сообщение об ошибке
};

class Person
{
public:
    Person(std::string name, unsigned age)
    {
        if (!age || age > 110) // если age==0 или age > 110
            throw person_error("Invalid age");
        this->name = name;
        this->age = age;
    }
    void print() const
    {
        std::cout << "Name: " << name << "\tAge: " << age << std::endl;
    }

private:
    std::string name;
    unsigned age;
};

void testPerson(std::string name, unsigned age)
{
    try
    {
        Person person{name, age}; // создаем один объект Person
        person.print();
    }
    catch (const person_error &err) // обработка ошибок, сязанных с Person
    {
        std::cout << "Person error: " << err.what() << std::endl;
    }
    catch (const std::exception &) // обработка остальных исключений
    {
        std::cout << "Something wrong" << std::endl;
    }
}
int main()
{
    testPerson("Tom", 38);  // Name: Tom       Age: 38
    testPerson("Sam", 250); // Person error: Invalid age
}
```